{"uuid": "c8c02f7b-d9ad-49d0-9afa-f44eb9b9c254", "children": ["5b7f5630-8cb0-4bcf-a830-43b3c455d5c3"], "befores": [{"name": "_xunit_setup_method_fixture_TestUserAuth", "status": "broken", "statusDetails": {"message": "requests.exceptions.ConnectionError: HTTPSConnectionPool(host='playground.learnqa.ru', port=443): Max retries exceeded with url: /api/user/login (Caused by NewConnectionError('<urllib3.connection.HTTPSConnection object at 0x7fa778125400>: Failed to establish a new connection: [Errno 8] nodename nor servname provided, or not known'))\n", "trace": "  File \"/Library/Frameworks/Python.framework/Versions/3.9/lib/python3.9/site-packages/pluggy/_callers.py\", line 39, in _multicall\n    res = hook_impl.function(*args)\n  File \"/Library/Frameworks/Python.framework/Versions/3.9/lib/python3.9/site-packages/_pytest/fixtures.py\", line 1111, in pytest_fixture_setup\n    result = call_fixture_func(fixturefunc, request, kwargs)\n  File \"/Library/Frameworks/Python.framework/Versions/3.9/lib/python3.9/site-packages/_pytest/fixtures.py\", line 883, in call_fixture_func\n    fixture_result = next(generator)\n  File \"/Library/Frameworks/Python.framework/Versions/3.9/lib/python3.9/site-packages/_pytest/python.py\", line 893, in xunit_setup_method_fixture\n    _call_with_optional_argument(func, method)\n  File \"/Library/Frameworks/Python.framework/Versions/3.9/lib/python3.9/site-packages/_pytest/python.py\", line 778, in _call_with_optional_argument\n    func()\n  File \"/Users/pavlovairisa/PycharmProjects/Rest_Api_Python/tests/test_user_auth.py\", line 20, in setup\n    response1 = MyRequests.post(\"/user/login\",data=data)\n  File \"/Users/pavlovairisa/PycharmProjects/Rest_Api_Python/lib/my_requests.py\", line 11, in post\n    return MyRequests._send(url, data, headers, cookies, 'POST')\n  File \"/Users/pavlovairisa/PycharmProjects/Rest_Api_Python/lib/my_requests.py\", line 42, in _send\n    response= requests.post(url, data=data, headers=headers, cookies=cookies)\n  File \"/Library/Frameworks/Python.framework/Versions/3.9/lib/python3.9/site-packages/requests/api.py\", line 115, in post\n    return request(\"post\", url, data=data, json=json, **kwargs)\n  File \"/Library/Frameworks/Python.framework/Versions/3.9/lib/python3.9/site-packages/requests/api.py\", line 59, in request\n    return session.request(method=method, url=url, **kwargs)\n  File \"/Library/Frameworks/Python.framework/Versions/3.9/lib/python3.9/site-packages/requests/sessions.py\", line 587, in request\n    resp = self.send(prep, **send_kwargs)\n  File \"/Library/Frameworks/Python.framework/Versions/3.9/lib/python3.9/site-packages/requests/sessions.py\", line 701, in send\n    r = adapter.send(request, **kwargs)\n  File \"/Library/Frameworks/Python.framework/Versions/3.9/lib/python3.9/site-packages/requests/adapters.py\", line 565, in send\n    raise ConnectionError(e, request=request)\n"}, "steps": [{"name": "POST request to URL '/user/login'", "status": "broken", "statusDetails": {"message": "requests.exceptions.ConnectionError: HTTPSConnectionPool(host='playground.learnqa.ru', port=443): Max retries exceeded with url: /api/user/login (Caused by NewConnectionError('<urllib3.connection.HTTPSConnection object at 0x7fa778125400>: Failed to establish a new connection: [Errno 8] nodename nor servname provided, or not known'))\n", "trace": "  File \"/Users/pavlovairisa/PycharmProjects/Rest_Api_Python/lib/my_requests.py\", line 11, in post\n    return MyRequests._send(url, data, headers, cookies, 'POST')\n  File \"/Users/pavlovairisa/PycharmProjects/Rest_Api_Python/lib/my_requests.py\", line 42, in _send\n    response= requests.post(url, data=data, headers=headers, cookies=cookies)\n  File \"/Library/Frameworks/Python.framework/Versions/3.9/lib/python3.9/site-packages/requests/api.py\", line 115, in post\n    return request(\"post\", url, data=data, json=json, **kwargs)\n  File \"/Library/Frameworks/Python.framework/Versions/3.9/lib/python3.9/site-packages/requests/api.py\", line 59, in request\n    return session.request(method=method, url=url, **kwargs)\n  File \"/Library/Frameworks/Python.framework/Versions/3.9/lib/python3.9/site-packages/requests/sessions.py\", line 587, in request\n    resp = self.send(prep, **send_kwargs)\n  File \"/Library/Frameworks/Python.framework/Versions/3.9/lib/python3.9/site-packages/requests/sessions.py\", line 701, in send\n    r = adapter.send(request, **kwargs)\n  File \"/Library/Frameworks/Python.framework/Versions/3.9/lib/python3.9/site-packages/requests/adapters.py\", line 565, in send\n    raise ConnectionError(e, request=request)\n"}, "start": 1660232788464, "stop": 1660232788466}], "start": 1660232788464, "stop": 1660232788466}], "start": 1660232788464, "stop": 1660232788555}